Workbook

Sheet Checklist
A1: STT | B1: Phase | C1: Công việc | D1: PIC | E1: Bắt đầu | F1: Kết thúc | G1: Thời lượng (ngày) | H1: Loại yêu cầu | I1: Tình trạng | J1: Tiến độ | K1: Ghi chú
A2: 1 | B2: Phase 0 – Chuẩn bị (Quyết định & Repo) | C2: Xác nhận phạm vi Phase 1: build đúng 6 agent theo MVP-Scope v3.4 (A01 Orchestrator kiến trúc đầy đủ + 5 agent nội dung B02/B03/D01/D02/E01) — KHÔNG build theo PRD đầy đủ (12 agent, Hindsight, ChromaDB, Meta, Analytics) | F2: =IF(E2="","",E2+ROUNDUP(G2,0)-1) | G2: 0.5 | H2: Quyết định | I2: Chưa bắt đầu | J2: 0 | K2: Ghi vào docs/decisions/0000, theo MVP-Scope v3.4 mục 1
A3: 2 | B3: Phase 0 – Chuẩn bị (Quyết định & Repo) | C3: Chốt ngưỡng đạt/không đạt của Evaluator (E01): Caption ≥7.0/10 VÀ Visual ≥3.5/5 — Trường & Thuận ký xác nhận | F3: =IF(E3="","",E3+ROUNDUP(G3,0)-1) | G3: 0.5 | H3: Quyết định | I3: Chưa bắt đầu | J3: 0 | K3: MVP-Scope v3.4 mục 5, đã đồng bộ PRD v3.2 - chỉ còn chờ ký
A4: 3 | B4: Phase 0 – Chuẩn bị (Quyết định & Repo) | C4: Chốt 4 mặc định tính năng phụ: không chạy chiến dịch ở Phase 1 (luôn Mode B) / form thương hiệu ngắn / lọc ảnh bằng tag / xin ảnh nhắn tay thủ công | F4: =IF(E4="","",E4+ROUNDUP(G4,0)-1) | G4: 0.5 | H4: Quyết định | I4: Chưa bắt đầu | J4: 0
A5: 4 | B5: Phase 0 – Chuẩn bị (Quyết định & Repo) | C5: Ghi nhận & khoanh vùng: PRD v1.2 (Tầng 4, do Thuận cập nhật) đã thiết kế lại Portal đầy đủ (Pixel Office, Kanban Task Board, Content Hub 3-tab) cho tầm nhìn full 12-agent — CHƯA thuộc phạm vi Portal đơn giản của Phase 1 | F5: =IF(E5="","",E5+ROUNDUP(G5,0)-1) | G5: 0.5 | H5: Quyết định | I5: Chưa bắt đầu | J5: 0 | K5: Cần Trường/Thuận xác nhận áp dụng thiết kế này từ Phase nào, tránh Antigravity tự build theo hướng Pixel Office khi đang làm Bước 6
A6: 5 | B6: Phase 0 – Chuẩn bị (Quyết định & Repo) | C6: Tạo repository GitHub (private), mời 2 thành viên | F6: =IF(E6="","",E6+ROUNDUP(G6,0)-1) | G6: 0.25 | H6: Hạ tầng | I6: Chưa bắt đầu | J6: 0
A7: 6 | B7: Phase 0 – Chuẩn bị (Quyết định & Repo) | C7: Thêm file hướng dẫn AI (AGENTS.md) vào gốc repo, cả 2 đọc kỹ 1 lượt | F7: =IF(E7="","",E7+ROUNDUP(G7,0)-1) | G7: 0.5 | H7: Tài liệu | I7: Chưa bắt đầu | J7: 0
A8: 7 | B8: Phase 0 – Chuẩn bị (Quyết định & Repo) | C8: Copy 2 tài liệu gốc mới nhất (PRD-CrewLab.md v1.2 + CrewLab-MVP-Scope-v3.4.md) vào docs/prd, giữ nguyên không sửa trực tiếp | F8: =IF(E8="","",E8+ROUNDUP(G8,0)-1) | G8: 0.25 | H8: Tài liệu | I8: Chưa bắt đầu | J8: 0
A9: 8 | B9: Phase 0 – Chuẩn bị (Quyết định & Repo) | C9: Phân chia phụ trách module: 1 người phụ trách Backend/Agent logic (A01 + 5 agent), 1 người phụ trách Portal & Internal App | F9: =IF(E9="","",E9+ROUNDUP(G9,0)-1) | G9: 0.25 | H9: Quyết định | I9: Chưa bắt đầu | J9: 0
A10: 9 | B10: Phase 0 – Chuẩn bị (Quyết định & Repo) | C10: Bật GitHub MCP trong Antigravity trên cả 2 máy | F10: =IF(E10="","",E10+ROUNDUP(G10,0)-1) | G10: 0.25 | H10: Hạ tầng | I10: Chưa bắt đầu | J10: 0
A11: 10 | B11: Phase 0 – Chuẩn bị (Quyết định & Repo) | C11: Bật bảo vệ nhánh main (bắt buộc qua Pull Request) | F11: =IF(E11="","",E11+ROUNDUP(G11,0)-1) | G11: 0.25 | H11: Hạ tầng | I11: Chưa bắt đầu | J11: 0
A12: 11 | B12: Phase 0 – Chuẩn bị (Quyết định & Repo) | C12: Setup bảng theo dõi công việc (GitHub Projects kanban) | F12: =IF(E12="","",E12+ROUNDUP(G12,0)-1) | G12: 0.5 | H12: Vận hành | I12: Chưa bắt đầu | J12: 0
A13: 12 | B13: Phase 1 – Bước 1: Hạ tầng (VPS/Coolify) | C13: Thuê & cấu hình VPS Hetzner CAX31 | F13: =IF(E13="","",E13+ROUNDUP(G13,0)-1) | G13: 0.5 | H13: Hạ tầng | I13: Chưa bắt đầu | J13: 0 | K13: MVP-Scope v3.4 mục 6 - bước 1, không spike Hindsight/Meta App Review
A14: 13 | B14: Phase 1 – Bước 1: Hạ tầng (VPS/Coolify) | C14: Cài Coolify lên VPS để deploy kiểu kéo-thả (git push tự deploy) | F14: =IF(E14="","",E14+ROUNDUP(G14,0)-1) | G14: 1 | H14: Hạ tầng | I14: Chưa bắt đầu | J14: 0
A15: 14 | B15: Phase 1 – Bước 1: Hạ tầng (VPS/Coolify) | C15: Tạo project Supabase Production (PostgreSQL + Auth + Storage) | F15: =IF(E15="","",E15+ROUNDUP(G15,0)-1) | G15: 0.5 | H15: Hạ tầng | I15: Chưa bắt đầu | J15: 0
A16: 15 | B16: Phase 1 – Bước 1: Hạ tầng (VPS/Coolify) | C16: Tạo project Supabase RIÊNG cho Staging (tách biệt hoàn toàn, không chung DB Production) | F16: =IF(E16="","",E16+ROUNDUP(G16,0)-1) | G16: 0.5 | H16: Hạ tầng | I16: Chưa bắt đầu | J16: 0
A17: 16 | B17: Phase 1 – Bước 1: Hạ tầng (VPS/Coolify) | C17: Đăng ký & trỏ domain: domain chính Client Portal, subdomain Internal App, domain Backend API | F17: =IF(E17="","",E17+ROUNDUP(G17,0)-1) | G17: 0.5 | H17: Hạ tầng | I17: Chưa bắt đầu | J17: 0
A18: 17 | B18: Phase 1 – Bước 1: Hạ tầng (VPS/Coolify) | C18: Cấu hình CORS & biến môi trường tách biệt Local/Staging/Production | F18: =IF(E18="","",E18+ROUNDUP(G18,0)-1) | G18: 0.5 | H18: Hạ tầng | I18: Chưa bắt đầu | J18: 0
A19: 18 | B19: Phase 1 – Bước 1: Hạ tầng (VPS/Coolify) | C19: Setup Redis (broker cho Celery) | F19: =IF(E19="","",E19+ROUNDUP(G19,0)-1) | G19: 0.5 | H19: Hạ tầng | I19: Chưa bắt đầu | J19: 0
A20: 19 | B20: Phase 1 – Bước 1: Hạ tầng (VPS/Coolify) | C20: Setup Celery Worker + Beat chạy nền cơ bản, thử chạy 1 task test | F20: =IF(E20="","",E20+ROUNDUP(G20,0)-1) | G20: 1 | H20: Hạ tầng | I20: Chưa bắt đầu | J20: 0
A21: 20 | B21: Phase 1 – Bước 1: Hạ tầng (VPS/Coolify) | C21: Setup CI/CD: push main tự động deploy qua Coolify | F21: =IF(E21="","",E21+ROUNDUP(G21,0)-1) | G21: 0.5 | H21: Hạ tầng | I21: Chưa bắt đầu | J21: 0
A22: 21 | B22: Phase 1 – Bước 2: Nền tảng dữ liệu (C1+C6+C7) | C22: Viết spec đầu tiên (spec.md): Database rút gọn — mọi agent khác phụ thuộc bảng này | F22: =IF(E22="","",E22+ROUNDUP(G22,0)-1) | G22: 0.5 | H22: Tài liệu | I22: Chưa bắt đầu | J22: 0 | K22: specs/0001-postgres-schema-mvp
A23: 22 | B23: Phase 1 – Bước 2: Nền tảng dữ liệu (C1+C6+C7) | C23: Bảng "Khách hàng" (clients) | F23: =IF(E23="","",E23+ROUNDUP(G23,0)-1) | G23: 1 | H23: Dữ liệu | I23: Chưa bắt đầu | J23: 0 | K23: C1
A24: 23 | B24: Phase 1 – Bước 2: Nền tảng dữ liệu (C1+C6+C7) | C24: Bảng "Người dùng" (users) 3 vai trò: agency_admin, client_admin, client_staff | F24: =IF(E24="","",E24+ROUNDUP(G24,0)-1) | G24: 1 | H24: Dữ liệu | I24: Chưa bắt đầu | J24: 0 | K24: C1
A25: 24 | B25: Phase 1 – Bước 2: Nền tảng dữ liệu (C1+C6+C7) | C25: Bảng "Cấu hình thương hiệu" (brand_settings) — versioned, không ghi đè bản cũ | F25: =IF(E25="","",E25+ROUNDUP(G25,0)-1) | G25: 1.5 | H25: Dữ liệu | I25: Chưa bắt đầu | J25: 0 | K25: C1
A26: 25 | B26: Phase 1 – Bước 2: Nền tảng dữ liệu (C1+C6+C7) | C26: Bảng "Trụ nội dung" (content_pillars) | F26: =IF(E26="","",E26+ROUNDUP(G26,0)-1) | G26: 0.5 | H26: Dữ liệu | I26: Chưa bắt đầu | J26: 0 | K26: C1
A27: 26 | B27: Phase 1 – Bước 2: Nền tảng dữ liệu (C1+C6+C7) | C27: Bảng "Bài đăng" (content_items) đủ FSM rút gọn: planned → ready_for_generation → caption_generating → visual_matching → waiting_asset → asset_blocked → visual_generating → evaluating → eval_failed ⟲ → pending_content_approval → approved_ready_to_post → posted / rejected / archived | F27: =IF(E27="","",E27+ROUNDUP(G27,0)-1) | G27: 1.5 | H27: Dữ liệu | I27: Chưa bắt đầu | J27: 0 | K27: C1 - nền tảng mọi agent khác. KHÔNG tạo bảng analytics_records ở Phase 1 (đã bỏ khỏi scope MVP, thuộc Phase 4)
A28: 27 | B28: Phase 1 – Bước 2: Nền tảng dữ liệu (C1+C6+C7) | C28: Bảng "Lịch sử duyệt" (hitl_reviews) — append-only | F28: =IF(E28="","",E28+ROUNDUP(G28,0)-1) | G28: 1 | H28: Dữ liệu | I28: Chưa bắt đầu | J28: 0 | K28: C1
A29: 28 | B29: Phase 1 – Bước 2: Nền tảng dữ liệu (C1+C6+C7) | C29: Bảng "Nhật ký thao tác" (audit_log) — append-only | F29: =IF(E29="","",E29+ROUNDUP(G29,0)-1) | G29: 1 | H29: Dữ liệu | I29: Chưa bắt đầu | J29: 0 | K29: C1
A30: 29 | B30: Phase 1 – Bước 2: Nền tảng dữ liệu (C1+C6+C7) | C30: Bảng "Trí nhớ Agent" agent_memory(agent_code, client_id, task_type, input_summary, output_summary, human_feedback, created_at) thay Hindsight | F30: =IF(E30="","",E30+ROUNDUP(G30,0)-1) | G30: 1 | H30: Dữ liệu | I30: Chưa bắt đầu | J30: 0 | K30: C3 rút gọn
A31: 30 | B31: Phase 1 – Bước 2: Nền tảng dữ liệu (C1+C6+C7) | C31: Bảng "Thư viện ảnh" (brand_assets) | F31: =IF(E31="","",E31+ROUNDUP(G31,0)-1) | G31: 1 | H31: Dữ liệu | I31: Chưa bắt đầu | J31: 0 | K31: C7
A32: 31 | B32: Phase 1 – Bước 2: Nền tảng dữ liệu (C1+C6+C7) | C32: Bảng "Yêu cầu xin ảnh" (asset_requests) — cần trường deadline cho job check_asset_request_expiry | F32: =IF(E32="","",E32+ROUNDUP(G32,0)-1) | G32: 1 | H32: Dữ liệu | I32: Chưa bắt đầu | J32: 0 | K32: C7
A33: 32 | B33: Phase 1 – Bước 2: Nền tảng dữ liệu (C1+C6+C7) | C33: Viết migration chạy được nhiều lần không lỗi, không làm mất dữ liệu cũ | F33: =IF(E33="","",E33+ROUNDUP(G33,0)-1) | G33: 1 | H33: Hạ tầng | I33: Chưa bắt đầu | J33: 0
A34: 33 | B34: Phase 1 – Bước 2: Nền tảng dữ liệu (C1+C6+C7) | C34: Bật RLS phân quyền theo dòng dữ liệu — mỗi khách hàng chỉ thấy đúng dữ liệu của mình | F34: =IF(E34="","",E34+ROUNDUP(G34,0)-1) | G34: 1.5 | H34: Dữ liệu | I34: Chưa bắt đầu | J34: 0 | K34: C6 Multi-tenant
A35: 34 | B35: Phase 1 – Bước 2: Nền tảng dữ liệu (C1+C6+C7) | C35: Kiểm thử: nhập dữ liệu sai trạng thái/sai định dạng phải bị hệ thống từ chối ngay | F35: =IF(E35="","",E35+ROUNDUP(G35,0)-1) | G35: 1 | H35: Kiểm thử | I35: Chưa bắt đầu | J35: 0
A36: 35 | B36: Phase 1 – Bước 2: Nền tảng dữ liệu (C1+C6+C7) | C36: Setup Supabase Storage theo cấu trúc thư mục riêng từng khách hàng | F36: =IF(E36="","",E36+ROUNDUP(G36,0)-1) | G36: 0.5 | H36: Hạ tầng | I36: Chưa bắt đầu | J36: 0 | K36: C7
A37: 36 | B37: Phase 1 – Bước 2: Nền tảng dữ liệu (C1+C6+C7) | C37: Xây lớp Tool Registry ~10 tool dùng chung cho 6 agent: T02/T03 (recall/retain trí nhớ, trỏ Postgres không Hindsight), T04 query_media_library (tag filter), T05 create_asset_request, T08/T09 (đọc/ghi content plan), T12/T13 (ảnh AI/ghép ảnh), T14/T15 (notify_agency_admin rút gọn / update_content_state) — agent CHỈ được gọi đúng tool trong danh sách này, không query DB thẳng | F37: =IF(E37="","",E37+ROUNDUP(G37,0)-1) | G37: 2 | H37: Dữ liệu | I37: Chưa bắt đầu | J37: 0 | K37: MVP-Scope v3.4 mục 4
A38: 37 | B38: Phase 1 – Bước 2: Nền tảng dữ liệu (C1+C6+C7) | C38: Cấu hình sao lưu (backup) tự động hàng ngày | F38: =IF(E38="","",E38+ROUNDUP(G38,0)-1) | G38: 0.5 | H38: Hạ tầng | I38: Chưa bắt đầu | J38: 0
A39: 38 | B39: Phase 1 – Bước 3: A01 Orchestrator | C39: Xây content_item_state_log + tool T15 update_content_state để từng agent tự ghi state bước mình vừa xong | F39: =IF(E39="","",E39+ROUNDUP(G39,0)-1) | G39: 1 | H39: Dữ liệu | I39: Chưa bắt đầu | J39: 0 | K39: Business Rule 6 - tránh 2 nơi cùng ghi 1 transition, race condition
A40: 39 | B40: Phase 1 – Bước 3: A01 Orchestrator | C40: Định nghĩa & wire đủ 10 trigger Active cho A01: beat_weekly, strategy_gate_approved(S2), strategy_gate_approved(S3), d01_complete, d02_complete(visual_ready), asset_submitted, asset_request_expired, eval_failed(còn retry), eval_failed(hard fail/hết lượt), content_gate_approved | F40: =IF(E40="","",E40+ROUNDUP(G40,0)-1) | G40: 3 | H40: Logic Agent (AI) | I40: Chưa bắt đầu | J40: 0 | K40: MVP-Scope v3.4 mục 1a - bảng Trigger Active vs Deferred
...

Sheet Tổng quan
A1: Phase / Bước | B1: Số công việc | C1: Tổng số ngày ước tính | D1: Tiêu chí Pass (điều kiện mở phase/bước kế tiếp)
A2: Phase 0 – Chuẩn bị (Quyết định & Repo) | B2: =COUNTIF(Checklist!$B:$B,"Phase 0 – Chuẩn bị (Quyết định & Repo)") -> 11 | C2: =SUMIF(Checklist!$B:$B,"Phase 0 – Chuẩn bị (Quyết định & Repo)",Checklist!$G:$G) -> 4.25 | D2: Không có tiêu chí Pass riêng — bước chuẩn bị, xong là chuyển sang Bước 1.
A3: Phase 1 – Bước 1: Hạ tầng (VPS/Coolify) | B3: =COUNTIF(Checklist!$B:$B,"Phase 1 – Bước 1: Hạ tầng (VPS/Coolify)") -> 9 | C3: =SUMIF(Checklist!$B:$B,"Phase 1 – Bước 1: Hạ tầng (VPS/Coolify)",Checklist!$G:$G) -> 5.5 | D3: Không có tiêu chí Pass riêng — gộp vào tiêu chí Pass chung của Phase 1 (xem dòng Phase 1 - TỔNG). Theo MVP-Scope v3.4 mục 6, KHÔNG còn ước lượng theo sprint/tuần, chỉ theo trình tự phụ thuộc.
A4: Phase 1 – Bước 2: Nền tảng dữ liệu (C1+C6+C7) | B4: =COUNTIF(Checklist!$B:$B,"Phase 1 – Bước 2: Nền tảng dữ liệu (C1+C6+C7)") -> 17 | C4: =SUMIF(Checklist!$B:$B,"Phase 1 – Bước 2: Nền tảng dữ liệu (C1+C6+C7)",Checklist!$G:$G) -> 17.5 | D4: Không có tiêu chí Pass riêng — gộp vào tiêu chí Pass chung của Phase 1.
A5: Phase 1 – Bước 3: A01 Orchestrator | B5: =COUNTIF(Checklist!$B:$B,"Phase 1 – Bước 3: A01 Orchestrator") -> 16 | C5: =SUMIF(Checklist!$B:$B,"Phase 1 – Bước 3: A01 Orchestrator",Checklist!$G:$G) -> 18.25 | D5: Không có tiêu chí Pass riêng — gộp vào tiêu chí Pass chung của Phase 1.
A6: Phase 1 – Bước 4: Context Packet MVP + P01-lite + Observability | B6: =COUNTIF(Checklist!$B:$B,"Phase 1 – Bước 4: Context Packet MVP + P01-lite + Observability") -> 11 | C6: =SUMIF(Checklist!$B:$B,"Phase 1 – Bước 4: Context Packet MVP + P01-lite + Observability",Checklist!$G:$G) -> 12 | D6: Không có tiêu chí Pass riêng — gộp vào tiêu chí Pass chung của Phase 1.
A7: Phase 1 – Bước 5: 5 Agent nội dung + FSM/Retry | B7: =COUNTIF(Checklist!$B:$B,"Phase 1 – Bước 5: 5 Agent nội dung + FSM/Retry") -> 34 | C7: =SUMIF(Checklist!$B:$B,"Phase 1 – Bước 5: 5 Agent nội dung + FSM/Retry",Checklist!$G:$G) -> 46 | D7: Không có tiêu chí Pass riêng — gộp vào tiêu chí Pass chung của Phase 1.
A8: Phase 1 – Bước 6: Portal + Internal App | B8: =COUNTIF(Checklist!$B:$B,"Phase 1 – Bước 6: Portal + Internal App") -> 13 | C8: =SUMIF(Checklist!$B:$B,"Phase 1 – Bước 6: Portal + Internal App",Checklist!$G:$G) -> 21.5 | D8: Không có tiêu chí Pass riêng — gộp vào tiêu chí Pass chung của Phase 1.
A9: Phase 1 – Bước 7: Hardening + Pilot thật | B9: =COUNTIF(Checklist!$B:$B,"Phase 1 – Bước 7: Hardening + Pilot thật") -> 11 | C9: =SUMIF(Checklist!$B:$B,"Phase 1 – Bước 7: Hardening + Pilot thật",Checklist!$G:$G) -> 10.5 | D9: Không có tiêu chí Pass riêng — gộp vào tiêu chí Pass chung của Phase 1.
A10: Phase 1 - TỔNG | B10: =COUNTIF(Checklist!$B:$B,"Phase 1*") -> 111 | C10: =SUMIF(Checklist!$B:$B,"Phase 1*",Checklist!$G:$G) -> 131.25 | D10: Chạy ≥2 chu kỳ tuần liên tục không cần can thiệp tay ngoài duyệt bài. agent_memory Recall thực sự dùng được bài học chu kỳ trước. Không worker/task treo >24h. Trường/Thuận (không phải Antigravity) xác nhận chất lượng caption/ảnh dùng được thật, không chỉ "chạy được".
A11: Phase 2 – Vận hành pilot & tinh chỉnh | B11: =COUNTIF(Checklist!$B:$B,"Phase 2 – Vận hành pilot & tinh chỉnh") -> 14 | C11: =SUMIF(Checklist!$B:$B,"Phase 2 – Vận hành pilot & tinh chỉnh",Checklist!$G:$G) -> 37 | D11: Đạt đủ KR rút gọn (chu kỳ ổn định, % duyệt lần đầu, thời gian duyệt) trong ≥4 tuần liên tục. Xác nhận rõ đăng tay có phải nút thắt cổ chai thật hay chưa, bằng công thức đã định.
A12: Phase 3 – Tự động đăng bài (Meta) | B12: =COUNTIF(Checklist!$B:$B,"Phase 3 – Tự động đăng bài (Meta)") -> 16 | C12: =SUMIF(Checklist!$B:$B,"Phase 3 – Tự động đăng bài (Meta)",Checklist!$G:$G) -> 24.5 | D12: OAuth kết nối ≤5 phút (đo thật). Tỷ lệ đăng bài thành công không cần can thiệp tay đạt mục tiêu. Thời gian tạo→đăng (qua duyệt) đạt mục tiêu.
A13: Phase 4 – Phân tích số liệu & học hỏi | B13: =COUNTIF(Checklist!$B:$B,"Phase 4 – Phân tích số liệu & học hỏi") -> 15 | C13: =SUMIF(Checklist!$B:$B,"Phase 4 – Phân tích số liệu & học hỏi",Checklist!$G:$G) -> 25 | D13: Vòng lặp đầy đủ tạo→duyệt→đăng→phân tích→học chạy liên tục nhiều tuần, không thao tác tay ngoài duyệt bài (đạt KR1 gốc). G04 đo được có cải thiện chất lượng content chu kỳ sau không.
A14: Phase 5 – Chiến lược đầy đủ (B01 + RAG) | B14: =COUNTIF(Checklist!$B:$B,"Phase 5 – Chiến lược đầy đủ (B01 + RAG)") -> 13 | C14: =SUMIF(Checklist!$B:$B,"Phase 5 – Chiến lược đầy đủ (B01 + RAG)",Checklist!$G:$G) -> 26 | D14: B01 tạo IMC Plan đúng thương hiệu, qua cổng duyệt S1 không cần sửa nhiều. Tìm kiếm ngữ nghĩa trả đúng ngữ cảnh khi test với tài liệu dài thật.
A15: Phase 6 – Mở rộng nhiều khách hàng | B15: =COUNTIF(Checklist!$B:$B,"Phase 6 – Mở rộng nhiều khách hàng") -> 10 | C15: =SUMIF(Checklist!$B:$B,"Phase 6 – Mở rộng nhiều khách hàng",Checklist!$G:$G) -> 20 | D15: ≥3-5 khách hàng chạy song song ổn định, không cần thêm người vận hành. Chi phí vận hành thêm 1 khách hàng mới ở mức thấp.
A16: Phase 7 – Đa dạng ngành & nâng cấp trí nhớ | B16: =COUNTIF(Checklist!$B:$B,"Phase 7 – Đa dạng ngành & nâng cấp trí nhớ") -> 4 | C16: =SUMIF(Checklist!$B:$B,"Phase 7 – Đa dạng ngành & nâng cấp trí nhớ",Checklist!$G:$G) -> 11 | D16: Không có tiêu chí kỹ thuật cứng — đây là quyết định kinh doanh, dựa vào kết quả thật của Phase 6.
A17: TỔNG CỘNG TOÀN DỰ ÁN | B17: =COUNTA(Checklist!$A2:$A195) -> 194 | C17: =SUM(Checklist!$G2:$G195) -> 279

Sheet Chú thích
A1: CÁCH DÙNG FILE NÀY
A2: • Sheet "Checklist": toàn bộ công việc, chia theo Phase 0 → Bước 1-7 của Phase 1 (đúng trình tự phụ thuộc ở MVP-Scope v3.4 mục 6) → Phase 2-7 (CrewLab-Phase-Roadmap.md).
A3: • Sheet "Tổng quan": số lượng công việc + tổng số ngày ước tính mỗi Phase/Bước, và Tiêu chí Pass để mở Phase kế tiếp.
A4: • Điền cột "Bắt đầu" (ngày thật) thì cột "Kết thúc" tự tính theo công thức (Bắt đầu + Thời lượng ước tính).
A5: • Cột "Thời lượng (ngày)" là ƯỚC LƯỢNG ban đầu để lập kế hoạch — MVP-Scope v3.4 đã chủ động bỏ ước lượng theo sprint/tuần vì tạo cảm giác chắc chắn giả; hãy tự đo tốc độ thật sau khi chạy xong Bước 1-4 rồi mới ước lượng phần còn lại.
A6: • Cột "Tình trạng" và "Loại yêu cầu" có sẵn dropdown. Dòng sẽ tự tô màu theo Tình trạng.
A7: • Lọc theo cột "Phase" để xem đúng việc của Bước hiện tại — đó là những gì nên giao cho Antigravity làm trong vài ngày tới. Trong Bước 1-7 của Phase 1, thứ tự các dòng ĐÃ được sắp theo đúng phụ thuộc kỹ thuật (bảng dữ liệu trước, A01 trước, Context Packet trước, rồi mới tới 5 agent nội dung).
A9: QUAN TRỌNG — PHẠM VI ĐANG BUILD
A10: Theo AGENTS.md: Phase 1 (Bước 1-7 trong sheet này) là phạm vi ĐANG được phép code thật — 6 agent chính thức: A01 Orchestrator (kiến trúc đầy đủ, 10/15 trigger active) + 5 agent nội dung B02, B03, D01, D02, E01.
A11: Phase 2 → Phase 7 trong sheet này CHỈ để nhìn thấy toàn cảnh lộ trình và lên kế hoạch — KHÔNG phải việc giao cho Antigravity code ngay.
A12: Nếu trong lúc làm Phase 1, Antigravity tự nhắc tới ChromaDB / F01 / G01-G04 / B01 / Meta OAuth / Telegram bot / Hindsight thật / Pixel Office-Kanban (toàn bộ nội dung Phase 3-7 và phần PRD v1.2 Tầng 4 nâng cao) → DỪNG LẠI, hỏi lại người, đừng để nó tự build theo bản đầy đủ.
A13: P01 ở Phase 1 chỉ là bản "P01-lite" (chỉ upsert human_feedback vào agent_memory) — bản P01 đầy đủ (learning packet, performance_patterns) thuộc Phase 4.
... A38: Cuối tuần: xem sheet Tổng quan, đối chiếu Tiêu chí Pass để biết Phase/Bước hiện tại đã đủ điều kiện đóng lại chưa.
